[2024-05-09T23:34:39.788+0000] {local_task_job_runner.py:120} INFO - ::group::Pre task execution logs
[2024-05-09T23:34:39.814+0000] {taskinstance.py:2076} INFO - Dependencies all met for dep_context=non-requeueable deps ti=<TaskInstance: ml_pipeline.clean_data manual__2024-05-09T23:23:25.210789+00:00 [queued]>
[2024-05-09T23:34:39.822+0000] {taskinstance.py:2076} INFO - Dependencies all met for dep_context=requeueable deps ti=<TaskInstance: ml_pipeline.clean_data manual__2024-05-09T23:23:25.210789+00:00 [queued]>
[2024-05-09T23:34:39.822+0000] {taskinstance.py:2306} INFO - Starting attempt 10 of 13
[2024-05-09T23:34:39.834+0000] {taskinstance.py:2330} INFO - Executing <Task(PythonOperator): clean_data> on 2024-05-09 23:23:25.210789+00:00
[2024-05-09T23:34:39.841+0000] {logging_mixin.py:188} WARNING - /home/***/.local/lib/python3.12/site-packages/***/task/task_runner/standard_task_runner.py:61 DeprecationWarning: This process (pid=3985) is multi-threaded, use of fork() may lead to deadlocks in the child.
[2024-05-09T23:34:39.841+0000] {standard_task_runner.py:90} INFO - Running: ['***', 'tasks', 'run', 'ml_pipeline', 'clean_data', 'manual__2024-05-09T23:23:25.210789+00:00', '--job-id', '158', '--raw', '--subdir', 'DAGS_FOLDER/main_dag.py', '--cfg-path', '/tmp/tmp8ajeg64s']
[2024-05-09T23:34:39.842+0000] {standard_task_runner.py:63} INFO - Started process 3990 to run task
[2024-05-09T23:34:39.842+0000] {standard_task_runner.py:91} INFO - Job 158: Subtask clean_data
[2024-05-09T23:34:39.854+0000] {logging_mixin.py:188} WARNING - /home/***/.local/lib/python3.12/site-packages/***/settings.py:195 DeprecationWarning: The sql_alchemy_conn option in [core] has been moved to the sql_alchemy_conn option in [database] - the old setting has been used, but please update your config.
[2024-05-09T23:34:39.886+0000] {task_command.py:426} INFO - Running <TaskInstance: ml_pipeline.clean_data manual__2024-05-09T23:23:25.210789+00:00 [running]> on host 3031e573f05c
[2024-05-09T23:34:39.972+0000] {taskinstance.py:2648} INFO - Exporting env vars: AIRFLOW_CTX_DAG_OWNER='***' AIRFLOW_CTX_DAG_ID='ml_pipeline' AIRFLOW_CTX_TASK_ID='clean_data' AIRFLOW_CTX_EXECUTION_DATE='2024-05-09T23:23:25.210789+00:00' AIRFLOW_CTX_TRY_NUMBER='10' AIRFLOW_CTX_DAG_RUN_ID='manual__2024-05-09T23:23:25.210789+00:00'
[2024-05-09T23:34:39.974+0000] {taskinstance.py:430} INFO - ::endgroup::
[2024-05-09T23:34:40.015+0000] {taskinstance.py:441} INFO - ::group::Post task execution logs
[2024-05-09T23:34:40.016+0000] {taskinstance.py:2905} ERROR - Task failed with exception
Traceback (most recent call last):
  File "/home/airflow/.local/lib/python3.12/site-packages/airflow/models/taskinstance.py", line 465, in _execute_task
    result = _execute_callable(context=context, **execute_callable_kwargs)
             ^^^^^^^^^^^^^^^^^^^^^^^^^^^^^^^^^^^^^^^^^^^^^^^^^^^^^^^^^^^^^
  File "/home/airflow/.local/lib/python3.12/site-packages/airflow/models/taskinstance.py", line 432, in _execute_callable
    return execute_callable(context=context, **execute_callable_kwargs)
           ^^^^^^^^^^^^^^^^^^^^^^^^^^^^^^^^^^^^^^^^^^^^^^^^^^^^^^^^^^^^
  File "/home/airflow/.local/lib/python3.12/site-packages/airflow/models/baseoperator.py", line 400, in wrapper
    return func(self, *args, **kwargs)
           ^^^^^^^^^^^^^^^^^^^^^^^^^^^
  File "/home/airflow/.local/lib/python3.12/site-packages/airflow/operators/python.py", line 235, in execute
    return_value = self.execute_callable()
                   ^^^^^^^^^^^^^^^^^^^^^^^
  File "/home/airflow/.local/lib/python3.12/site-packages/airflow/operators/python.py", line 252, in execute_callable
    return self.python_callable(*self.op_args, **self.op_kwargs)
           ^^^^^^^^^^^^^^^^^^^^^^^^^^^^^^^^^^^^^^^^^^^^^^^^^^^^^
  File "/opt/airflow/dags/tasks/clean_data.py", line 28, in clean_data
    df.drop_duplicates(inplace=True)
  File "/home/airflow/.local/lib/python3.12/site-packages/pandas/core/frame.py", line 6566, in drop_duplicates
    result = self[-self.duplicated(subset, keep=keep)]
                   ^^^^^^^^^^^^^^^^^^^^^^^^^^^^^^^^^^
  File "/home/airflow/.local/lib/python3.12/site-packages/pandas/core/frame.py", line 6706, in duplicated
    labels, shape = map(list, zip(*map(f, vals)))
                              ^^^^^^^^^^^^^^^^^^
  File "/home/airflow/.local/lib/python3.12/site-packages/pandas/core/frame.py", line 6674, in f
    labels, shape = algorithms.factorize(vals, size_hint=len(self))
                    ^^^^^^^^^^^^^^^^^^^^^^^^^^^^^^^^^^^^^^^^^^^^^^^
  File "/home/airflow/.local/lib/python3.12/site-packages/pandas/core/algorithms.py", line 795, in factorize
    codes, uniques = factorize_array(
                     ^^^^^^^^^^^^^^^^
  File "/home/airflow/.local/lib/python3.12/site-packages/pandas/core/algorithms.py", line 595, in factorize_array
    uniques, codes = table.factorize(
                     ^^^^^^^^^^^^^^^^
  File "pandas/_libs/hashtable_class_helper.pxi", line 7280, in pandas._libs.hashtable.PyObjectHashTable.factorize
  File "pandas/_libs/hashtable_class_helper.pxi", line 7194, in pandas._libs.hashtable.PyObjectHashTable._unique
TypeError: unhashable type: 'list'
[2024-05-09T23:34:40.035+0000] {taskinstance.py:1206} INFO - Marking task as UP_FOR_RETRY. dag_id=ml_pipeline, task_id=clean_data, run_id=manual__2024-05-09T23:23:25.210789+00:00, execution_date=20240509T232325, start_date=20240509T233439, end_date=20240509T233440
[2024-05-09T23:34:40.050+0000] {standard_task_runner.py:110} ERROR - Failed to execute job 158 for task clean_data (unhashable type: 'list'; 3990)
[2024-05-09T23:34:40.096+0000] {local_task_job_runner.py:240} INFO - Task exited with return code 1
[2024-05-09T23:34:40.130+0000] {taskinstance.py:3498} INFO - 0 downstream tasks scheduled from follow-on schedule check
[2024-05-09T23:34:40.133+0000] {local_task_job_runner.py:222} INFO - ::endgroup::
