[2024-05-10T03:11:03.626+0000] {task_context_logger.py:104} ERROR - Executor reports task instance <TaskInstance: ml_pipeline.concat_data manual__2024-05-09T23:55:21.313175+00:00 [queued]> finished (failed) although the task says it's queued. (Info: None) Was the task killed externally?
