[2024-05-09T16:28:28.557+0000] {local_task_job_runner.py:120} INFO - ::group::Pre task execution logs
[2024-05-09T16:28:28.585+0000] {taskinstance.py:2076} INFO - Dependencies all met for dep_context=non-requeueable deps ti=<TaskInstance: ml_pipeline.data_to_csv manual__2024-05-09T16:23:09.223600+00:00 [queued]>
[2024-05-09T16:28:28.594+0000] {taskinstance.py:2076} INFO - Dependencies all met for dep_context=requeueable deps ti=<TaskInstance: ml_pipeline.data_to_csv manual__2024-05-09T16:23:09.223600+00:00 [queued]>
[2024-05-09T16:28:28.595+0000] {taskinstance.py:2306} INFO - Starting attempt 2 of 4
[2024-05-09T16:28:28.606+0000] {taskinstance.py:2330} INFO - Executing <Task(PythonOperator): data_to_csv> on 2024-05-09 16:23:09.223600+00:00
[2024-05-09T16:28:28.615+0000] {logging_mixin.py:188} WARNING - /home/***/.local/lib/python3.12/site-packages/***/task/task_runner/standard_task_runner.py:61 DeprecationWarning: This process (pid=374) is multi-threaded, use of fork() may lead to deadlocks in the child.
[2024-05-09T16:28:28.616+0000] {standard_task_runner.py:63} INFO - Started process 376 to run task
[2024-05-09T16:28:28.615+0000] {standard_task_runner.py:90} INFO - Running: ['***', 'tasks', 'run', 'ml_pipeline', 'data_to_csv', 'manual__2024-05-09T16:23:09.223600+00:00', '--job-id', '22', '--raw', '--subdir', 'DAGS_FOLDER/main_dag.py', '--cfg-path', '/tmp/tmpqh1bqxzl']
[2024-05-09T16:28:28.617+0000] {standard_task_runner.py:91} INFO - Job 22: Subtask data_to_csv
[2024-05-09T16:28:28.630+0000] {logging_mixin.py:188} WARNING - /home/***/.local/lib/python3.12/site-packages/***/settings.py:195 DeprecationWarning: The sql_alchemy_conn option in [core] has been moved to the sql_alchemy_conn option in [database] - the old setting has been used, but please update your config.
[2024-05-09T16:28:28.664+0000] {task_command.py:426} INFO - Running <TaskInstance: ml_pipeline.data_to_csv manual__2024-05-09T16:23:09.223600+00:00 [running]> on host c78fa7b1ea7a
[2024-05-09T16:28:28.744+0000] {taskinstance.py:2648} INFO - Exporting env vars: AIRFLOW_CTX_DAG_OWNER='***' AIRFLOW_CTX_DAG_ID='ml_pipeline' AIRFLOW_CTX_TASK_ID='data_to_csv' AIRFLOW_CTX_EXECUTION_DATE='2024-05-09T16:23:09.223600+00:00' AIRFLOW_CTX_TRY_NUMBER='2' AIRFLOW_CTX_DAG_RUN_ID='manual__2024-05-09T16:23:09.223600+00:00'
[2024-05-09T16:28:28.745+0000] {taskinstance.py:430} INFO - ::endgroup::
[2024-05-09T16:28:28.764+0000] {connectionpool.py:874} WARNING - Retrying (Retry(total=4, connect=None, read=None, redirect=None, status=None)) after connection broken by 'NewConnectionError('<urllib3.connection.HTTPConnection object at 0x7f5ef4f6ac30>: Failed to establish a new connection: [Errno 111] Connection refused')': /datapipeline?location=
[2024-05-09T16:28:29.165+0000] {connectionpool.py:874} WARNING - Retrying (Retry(total=3, connect=None, read=None, redirect=None, status=None)) after connection broken by 'NewConnectionError('<urllib3.connection.HTTPConnection object at 0x7f5ef4f6af60>: Failed to establish a new connection: [Errno 111] Connection refused')': /datapipeline?location=
[2024-05-09T16:28:29.966+0000] {connectionpool.py:874} WARNING - Retrying (Retry(total=2, connect=None, read=None, redirect=None, status=None)) after connection broken by 'NewConnectionError('<urllib3.connection.HTTPConnection object at 0x7f5ef4f6b260>: Failed to establish a new connection: [Errno 111] Connection refused')': /datapipeline?location=
[2024-05-09T16:28:31.567+0000] {connectionpool.py:874} WARNING - Retrying (Retry(total=1, connect=None, read=None, redirect=None, status=None)) after connection broken by 'NewConnectionError('<urllib3.connection.HTTPConnection object at 0x7f5ef4f6b770>: Failed to establish a new connection: [Errno 111] Connection refused')': /datapipeline?location=
[2024-05-09T16:28:34.769+0000] {connectionpool.py:874} WARNING - Retrying (Retry(total=0, connect=None, read=None, redirect=None, status=None)) after connection broken by 'NewConnectionError('<urllib3.connection.HTTPConnection object at 0x7f5ef4f6bcb0>: Failed to establish a new connection: [Errno 111] Connection refused')': /datapipeline?location=
[2024-05-09T16:28:34.770+0000] {taskinstance.py:441} INFO - ::group::Post task execution logs
[2024-05-09T16:28:34.770+0000] {taskinstance.py:2905} ERROR - Task failed with exception
Traceback (most recent call last):
  File "/home/airflow/.local/lib/python3.12/site-packages/urllib3/connection.py", line 198, in _new_conn
    sock = connection.create_connection(
           ^^^^^^^^^^^^^^^^^^^^^^^^^^^^^
  File "/home/airflow/.local/lib/python3.12/site-packages/urllib3/util/connection.py", line 85, in create_connection
    raise err
  File "/home/airflow/.local/lib/python3.12/site-packages/urllib3/util/connection.py", line 73, in create_connection
    sock.connect(sa)
ConnectionRefusedError: [Errno 111] Connection refused

The above exception was the direct cause of the following exception:

Traceback (most recent call last):
  File "/home/airflow/.local/lib/python3.12/site-packages/urllib3/connectionpool.py", line 793, in urlopen
    response = self._make_request(
               ^^^^^^^^^^^^^^^^^^^
  File "/home/airflow/.local/lib/python3.12/site-packages/urllib3/connectionpool.py", line 496, in _make_request
    conn.request(
  File "/home/airflow/.local/lib/python3.12/site-packages/urllib3/connection.py", line 400, in request
    self.endheaders()
  File "/usr/local/lib/python3.12/http/client.py", line 1331, in endheaders
    self._send_output(message_body, encode_chunked=encode_chunked)
  File "/usr/local/lib/python3.12/http/client.py", line 1091, in _send_output
    self.send(msg)
  File "/usr/local/lib/python3.12/http/client.py", line 1035, in send
    self.connect()
  File "/home/airflow/.local/lib/python3.12/site-packages/urllib3/connection.py", line 238, in connect
    self.sock = self._new_conn()
                ^^^^^^^^^^^^^^^^
  File "/home/airflow/.local/lib/python3.12/site-packages/urllib3/connection.py", line 213, in _new_conn
    raise NewConnectionError(
urllib3.exceptions.NewConnectionError: <urllib3.connection.HTTPConnection object at 0x7f5ef4fa4080>: Failed to establish a new connection: [Errno 111] Connection refused

The above exception was the direct cause of the following exception:

Traceback (most recent call last):
  File "/home/airflow/.local/lib/python3.12/site-packages/airflow/models/taskinstance.py", line 465, in _execute_task
    result = _execute_callable(context=context, **execute_callable_kwargs)
             ^^^^^^^^^^^^^^^^^^^^^^^^^^^^^^^^^^^^^^^^^^^^^^^^^^^^^^^^^^^^^
  File "/home/airflow/.local/lib/python3.12/site-packages/airflow/models/taskinstance.py", line 432, in _execute_callable
    return execute_callable(context=context, **execute_callable_kwargs)
           ^^^^^^^^^^^^^^^^^^^^^^^^^^^^^^^^^^^^^^^^^^^^^^^^^^^^^^^^^^^^
  File "/home/airflow/.local/lib/python3.12/site-packages/airflow/models/baseoperator.py", line 400, in wrapper
    return func(self, *args, **kwargs)
           ^^^^^^^^^^^^^^^^^^^^^^^^^^^
  File "/home/airflow/.local/lib/python3.12/site-packages/airflow/operators/python.py", line 235, in execute
    return_value = self.execute_callable()
                   ^^^^^^^^^^^^^^^^^^^^^^^
  File "/home/airflow/.local/lib/python3.12/site-packages/airflow/operators/python.py", line 252, in execute_callable
    return self.python_callable(*self.op_args, **self.op_kwargs)
           ^^^^^^^^^^^^^^^^^^^^^^^^^^^^^^^^^^^^^^^^^^^^^^^^^^^^^
  File "/opt/airflow/dags/tasks/extract_data.py", line 99, in extract_api_data
    for obj in minio_client.list_objects(bucket_name, prefix='data/api_data_json/'):
  File "/home/airflow/.local/lib/python3.12/site-packages/minio/api.py", line 3109, in _list_objects
    response = self._execute(
               ^^^^^^^^^^^^^^
  File "/home/airflow/.local/lib/python3.12/site-packages/minio/api.py", line 437, in _execute
    region = self._get_region(bucket_name)
             ^^^^^^^^^^^^^^^^^^^^^^^^^^^^^
  File "/home/airflow/.local/lib/python3.12/site-packages/minio/api.py", line 494, in _get_region
    response = self._url_open(
               ^^^^^^^^^^^^^^^
  File "/home/airflow/.local/lib/python3.12/site-packages/minio/api.py", line 302, in _url_open
    response = self._http.urlopen(
               ^^^^^^^^^^^^^^^^^^^
  File "/home/airflow/.local/lib/python3.12/site-packages/urllib3/poolmanager.py", line 444, in urlopen
    response = conn.urlopen(method, u.request_uri, **kw)
               ^^^^^^^^^^^^^^^^^^^^^^^^^^^^^^^^^^^^^^^^^
  File "/home/airflow/.local/lib/python3.12/site-packages/urllib3/connectionpool.py", line 877, in urlopen
    return self.urlopen(
           ^^^^^^^^^^^^^
  File "/home/airflow/.local/lib/python3.12/site-packages/urllib3/connectionpool.py", line 877, in urlopen
    return self.urlopen(
           ^^^^^^^^^^^^^
  File "/home/airflow/.local/lib/python3.12/site-packages/urllib3/connectionpool.py", line 877, in urlopen
    return self.urlopen(
           ^^^^^^^^^^^^^
  [Previous line repeated 2 more times]
  File "/home/airflow/.local/lib/python3.12/site-packages/urllib3/connectionpool.py", line 847, in urlopen
    retries = retries.increment(
              ^^^^^^^^^^^^^^^^^^
  File "/home/airflow/.local/lib/python3.12/site-packages/urllib3/util/retry.py", line 515, in increment
    raise MaxRetryError(_pool, url, reason) from reason  # type: ignore[arg-type]
    ^^^^^^^^^^^^^^^^^^^^^^^^^^^^^^^^^^^^^^^^^^^^^^^^^^^
urllib3.exceptions.MaxRetryError: HTTPConnectionPool(host='localhost', port=9000): Max retries exceeded with url: /datapipeline?location= (Caused by NewConnectionError('<urllib3.connection.HTTPConnection object at 0x7f5ef4fa4080>: Failed to establish a new connection: [Errno 111] Connection refused'))
[2024-05-09T16:28:34.785+0000] {taskinstance.py:1206} INFO - Marking task as UP_FOR_RETRY. dag_id=ml_pipeline, task_id=data_to_csv, run_id=manual__2024-05-09T16:23:09.223600+00:00, execution_date=20240509T162309, start_date=20240509T162828, end_date=20240509T162834
[2024-05-09T16:28:34.798+0000] {standard_task_runner.py:110} ERROR - Failed to execute job 22 for task data_to_csv (HTTPConnectionPool(host='localhost', port=9000): Max retries exceeded with url: /datapipeline?location= (Caused by NewConnectionError('<urllib3.connection.HTTPConnection object at 0x7f5ef4fa4080>: Failed to establish a new connection: [Errno 111] Connection refused')); 376)
[2024-05-09T16:28:34.838+0000] {local_task_job_runner.py:240} INFO - Task exited with return code 1
[2024-05-09T16:28:34.863+0000] {taskinstance.py:3498} INFO - 0 downstream tasks scheduled from follow-on schedule check
[2024-05-09T16:28:34.876+0000] {local_task_job_runner.py:222} INFO - ::endgroup::
