[2024-05-10T09:59:54.280+0000] {local_task_job_runner.py:120} INFO - ::group::Pre task execution logs
[2024-05-10T09:59:54.304+0000] {taskinstance.py:2076} INFO - Dependencies all met for dep_context=non-requeueable deps ti=<TaskInstance: data_pipeline.clean_api_data manual__2024-05-10T09:58:46.082243+00:00 [queued]>
[2024-05-10T09:59:54.310+0000] {taskinstance.py:2076} INFO - Dependencies all met for dep_context=requeueable deps ti=<TaskInstance: data_pipeline.clean_api_data manual__2024-05-10T09:58:46.082243+00:00 [queued]>
[2024-05-10T09:59:54.311+0000] {taskinstance.py:2306} INFO - Starting attempt 1 of 4
[2024-05-10T09:59:54.321+0000] {taskinstance.py:2330} INFO - Executing <Task(PythonOperator): clean_api_data> on 2024-05-10 09:58:46.082243+00:00
[2024-05-10T09:59:54.327+0000] {logging_mixin.py:188} WARNING - /home/***/.local/lib/python3.12/site-packages/***/task/task_runner/standard_task_runner.py:61 DeprecationWarning: This process (pid=215) is multi-threaded, use of fork() may lead to deadlocks in the child.
[2024-05-10T09:59:54.328+0000] {standard_task_runner.py:63} INFO - Started process 217 to run task
[2024-05-10T09:59:54.327+0000] {standard_task_runner.py:90} INFO - Running: ['***', 'tasks', 'run', 'data_pipeline', 'clean_api_data', 'manual__2024-05-10T09:58:46.082243+00:00', '--job-id', '348', '--raw', '--subdir', 'DAGS_FOLDER/main_dag.py', '--cfg-path', '/tmp/tmp7oxnj5l1']
[2024-05-10T09:59:54.328+0000] {standard_task_runner.py:91} INFO - Job 348: Subtask clean_api_data
[2024-05-10T09:59:54.338+0000] {logging_mixin.py:188} WARNING - /home/***/.local/lib/python3.12/site-packages/***/settings.py:195 DeprecationWarning: The sql_alchemy_conn option in [core] has been moved to the sql_alchemy_conn option in [database] - the old setting has been used, but please update your config.
[2024-05-10T09:59:54.365+0000] {task_command.py:426} INFO - Running <TaskInstance: data_pipeline.clean_api_data manual__2024-05-10T09:58:46.082243+00:00 [running]> on host dbfcb70dcca2
[2024-05-10T09:59:54.436+0000] {taskinstance.py:2648} INFO - Exporting env vars: AIRFLOW_CTX_DAG_OWNER='***' AIRFLOW_CTX_DAG_ID='data_pipeline' AIRFLOW_CTX_TASK_ID='clean_api_data' AIRFLOW_CTX_EXECUTION_DATE='2024-05-10T09:58:46.082243+00:00' AIRFLOW_CTX_TRY_NUMBER='1' AIRFLOW_CTX_DAG_RUN_ID='manual__2024-05-10T09:58:46.082243+00:00'
[2024-05-10T09:59:54.437+0000] {taskinstance.py:430} INFO - ::endgroup::
[2024-05-10T09:59:54.502+0000] {taskinstance.py:441} INFO - ::group::Post task execution logs
[2024-05-10T09:59:54.503+0000] {taskinstance.py:2905} ERROR - Task failed with exception
Traceback (most recent call last):
  File "/home/airflow/.local/lib/python3.12/site-packages/airflow/models/taskinstance.py", line 465, in _execute_task
    result = _execute_callable(context=context, **execute_callable_kwargs)
             ^^^^^^^^^^^^^^^^^^^^^^^^^^^^^^^^^^^^^^^^^^^^^^^^^^^^^^^^^^^^^
  File "/home/airflow/.local/lib/python3.12/site-packages/airflow/models/taskinstance.py", line 432, in _execute_callable
    return execute_callable(context=context, **execute_callable_kwargs)
           ^^^^^^^^^^^^^^^^^^^^^^^^^^^^^^^^^^^^^^^^^^^^^^^^^^^^^^^^^^^^
  File "/home/airflow/.local/lib/python3.12/site-packages/airflow/models/baseoperator.py", line 400, in wrapper
    return func(self, *args, **kwargs)
           ^^^^^^^^^^^^^^^^^^^^^^^^^^^
  File "/home/airflow/.local/lib/python3.12/site-packages/airflow/operators/python.py", line 235, in execute
    return_value = self.execute_callable()
                   ^^^^^^^^^^^^^^^^^^^^^^^
  File "/home/airflow/.local/lib/python3.12/site-packages/airflow/operators/python.py", line 252, in execute_callable
    return self.python_callable(*self.op_args, **self.op_kwargs)
           ^^^^^^^^^^^^^^^^^^^^^^^^^^^^^^^^^^^^^^^^^^^^^^^^^^^^^
  File "/opt/airflow/dags/tasks/clean_data.py", line 62, in clean_api_data
    df = df.apply(lambda x: cleanse_unicode(x))
         ^^^^^^^^^^^^^^^^^^^^^^^^^^^^^^^^^^^^^^
  File "/home/airflow/.local/lib/python3.12/site-packages/pandas/core/frame.py", line 10034, in apply
    return op.apply().__finalize__(self, method="apply")
           ^^^^^^^^^^
  File "/home/airflow/.local/lib/python3.12/site-packages/pandas/core/apply.py", line 837, in apply
    return self.apply_standard()
           ^^^^^^^^^^^^^^^^^^^^^
  File "/home/airflow/.local/lib/python3.12/site-packages/pandas/core/apply.py", line 965, in apply_standard
    results, res_index = self.apply_series_generator()
                         ^^^^^^^^^^^^^^^^^^^^^^^^^^^^^
  File "/home/airflow/.local/lib/python3.12/site-packages/pandas/core/apply.py", line 981, in apply_series_generator
    results[i] = self.func(v, *self.args, **self.kwargs)
                 ^^^^^^^^^^^^^^^^^^^^^^^^^^^^^^^^^^^^^^^
  File "/opt/airflow/dags/tasks/clean_data.py", line 62, in <lambda>
    df = df.apply(lambda x: cleanse_unicode(x))
                            ^^^^^^^^^^^^^^^^^^
  File "/opt/airflow/dags/tasks/clean_data.py", line 8, in cleanse_unicode
    if not s:
           ^
  File "/home/airflow/.local/lib/python3.12/site-packages/pandas/core/generic.py", line 1519, in __nonzero__
    raise ValueError(
ValueError: The truth value of a Series is ambiguous. Use a.empty, a.bool(), a.item(), a.any() or a.all().
[2024-05-10T09:59:54.517+0000] {taskinstance.py:1206} INFO - Marking task as UP_FOR_RETRY. dag_id=data_pipeline, task_id=clean_api_data, run_id=manual__2024-05-10T09:58:46.082243+00:00, execution_date=20240510T095846, start_date=20240510T095954, end_date=20240510T095954
[2024-05-10T09:59:54.530+0000] {standard_task_runner.py:110} ERROR - Failed to execute job 348 for task clean_api_data (The truth value of a Series is ambiguous. Use a.empty, a.bool(), a.item(), a.any() or a.all().; 217)
[2024-05-10T09:59:54.541+0000] {local_task_job_runner.py:240} INFO - Task exited with return code 1
[2024-05-10T09:59:54.559+0000] {taskinstance.py:3498} INFO - 0 downstream tasks scheduled from follow-on schedule check
[2024-05-10T09:59:54.560+0000] {local_task_job_runner.py:222} INFO - ::endgroup::
