[2024-05-10T07:31:00.703+0000] {task_context_logger.py:104} ERROR - Executor reports task instance <TaskInstance: data_pipeline.concat_data manual__2024-05-10T07:28:51.301077+00:00 [queued]> finished (failed) although the task says it's queued. (Info: None) Was the task killed externally?
