[2024-05-10T07:29:27.881+0000] {local_task_job_runner.py:120} INFO - ::group::Pre task execution logs
[2024-05-10T07:29:27.902+0000] {taskinstance.py:2076} INFO - Dependencies all met for dep_context=non-requeueable deps ti=<TaskInstance: data_pipeline.concat_data manual__2024-05-10T07:28:51.301077+00:00 [queued]>
[2024-05-10T07:29:27.908+0000] {taskinstance.py:2076} INFO - Dependencies all met for dep_context=requeueable deps ti=<TaskInstance: data_pipeline.concat_data manual__2024-05-10T07:28:51.301077+00:00 [queued]>
[2024-05-10T07:29:27.909+0000] {taskinstance.py:2306} INFO - Starting attempt 1 of 4
[2024-05-10T07:29:27.919+0000] {taskinstance.py:2330} INFO - Executing <Task(PythonOperator): concat_data> on 2024-05-10 07:28:51.301077+00:00
[2024-05-10T07:29:27.927+0000] {logging_mixin.py:188} WARNING - /home/***/.local/lib/python3.12/site-packages/***/task/task_runner/standard_task_runner.py:61 DeprecationWarning: This process (pid=20473) is multi-threaded, use of fork() may lead to deadlocks in the child.
[2024-05-10T07:29:27.928+0000] {standard_task_runner.py:63} INFO - Started process 20475 to run task
[2024-05-10T07:29:27.927+0000] {standard_task_runner.py:90} INFO - Running: ['***', 'tasks', 'run', 'data_pipeline', 'concat_data', 'manual__2024-05-10T07:28:51.301077+00:00', '--job-id', '304', '--raw', '--subdir', 'DAGS_FOLDER/main_dag.py', '--cfg-path', '/tmp/tmp6h5st8n2']
[2024-05-10T07:29:27.929+0000] {standard_task_runner.py:91} INFO - Job 304: Subtask concat_data
[2024-05-10T07:29:27.939+0000] {logging_mixin.py:188} WARNING - /home/***/.local/lib/python3.12/site-packages/***/settings.py:195 DeprecationWarning: The sql_alchemy_conn option in [core] has been moved to the sql_alchemy_conn option in [database] - the old setting has been used, but please update your config.
[2024-05-10T07:29:27.965+0000] {task_command.py:426} INFO - Running <TaskInstance: data_pipeline.concat_data manual__2024-05-10T07:28:51.301077+00:00 [running]> on host 3031e573f05c
[2024-05-10T07:29:28.032+0000] {taskinstance.py:2648} INFO - Exporting env vars: AIRFLOW_CTX_DAG_OWNER='***' AIRFLOW_CTX_DAG_ID='data_pipeline' AIRFLOW_CTX_TASK_ID='concat_data' AIRFLOW_CTX_EXECUTION_DATE='2024-05-10T07:28:51.301077+00:00' AIRFLOW_CTX_TRY_NUMBER='1' AIRFLOW_CTX_DAG_RUN_ID='manual__2024-05-10T07:28:51.301077+00:00'
[2024-05-10T07:29:28.033+0000] {taskinstance.py:430} INFO - ::endgroup::
[2024-05-10T07:29:28.109+0000] {taskinstance.py:441} INFO - ::group::Post task execution logs
[2024-05-10T07:29:28.110+0000] {taskinstance.py:2905} ERROR - Task failed with exception
Traceback (most recent call last):
  File "/home/airflow/.local/lib/python3.12/site-packages/airflow/models/taskinstance.py", line 465, in _execute_task
    result = _execute_callable(context=context, **execute_callable_kwargs)
             ^^^^^^^^^^^^^^^^^^^^^^^^^^^^^^^^^^^^^^^^^^^^^^^^^^^^^^^^^^^^^
  File "/home/airflow/.local/lib/python3.12/site-packages/airflow/models/taskinstance.py", line 432, in _execute_callable
    return execute_callable(context=context, **execute_callable_kwargs)
           ^^^^^^^^^^^^^^^^^^^^^^^^^^^^^^^^^^^^^^^^^^^^^^^^^^^^^^^^^^^^
  File "/home/airflow/.local/lib/python3.12/site-packages/airflow/models/baseoperator.py", line 400, in wrapper
    return func(self, *args, **kwargs)
           ^^^^^^^^^^^^^^^^^^^^^^^^^^^
  File "/home/airflow/.local/lib/python3.12/site-packages/airflow/operators/python.py", line 235, in execute
    return_value = self.execute_callable()
                   ^^^^^^^^^^^^^^^^^^^^^^^
  File "/home/airflow/.local/lib/python3.12/site-packages/airflow/operators/python.py", line 252, in execute_callable
    return self.python_callable(*self.op_args, **self.op_kwargs)
           ^^^^^^^^^^^^^^^^^^^^^^^^^^^^^^^^^^^^^^^^^^^^^^^^^^^^^
  File "/opt/airflow/dags/tasks/concat_data.py", line 29, in concat_data
    minio_client.fget_object(bucket_name, database_file_path, file_path_to_upload)
  File "/home/airflow/.local/lib/python3.12/site-packages/minio/api.py", line 1118, in fget_object
    stat = self.stat_object(
           ^^^^^^^^^^^^^^^^^
  File "/home/airflow/.local/lib/python3.12/site-packages/minio/api.py", line 2043, in stat_object
    response = self._execute(
               ^^^^^^^^^^^^^^
  File "/home/airflow/.local/lib/python3.12/site-packages/minio/api.py", line 440, in _execute
    return self._url_open(
           ^^^^^^^^^^^^^^^
  File "/home/airflow/.local/lib/python3.12/site-packages/minio/api.py", line 423, in _url_open
    raise response_error
minio.error.S3Error: S3 operation failed; code: NoSuchKey, message: Object does not exist, resource: /datapipeline/data/database.csv, request_id: 17CE100FCC11CD89, host_id: dd9025bab4ad464b049177c95eb6ebf374d3b3fd1af9251148b658df7ac2e3e8, bucket_name: datapipeline, object_name: data/database.csv
[2024-05-10T07:29:28.175+0000] {taskinstance.py:1206} INFO - Marking task as UP_FOR_RETRY. dag_id=data_pipeline, task_id=concat_data, run_id=manual__2024-05-10T07:28:51.301077+00:00, execution_date=20240510T072851, start_date=20240510T072927, end_date=20240510T072928
[2024-05-10T07:29:28.186+0000] {standard_task_runner.py:110} ERROR - Failed to execute job 304 for task concat_data (S3 operation failed; code: NoSuchKey, message: Object does not exist, resource: /datapipeline/data/database.csv, request_id: 17CE100FCC11CD89, host_id: dd9025bab4ad464b049177c95eb6ebf374d3b3fd1af9251148b658df7ac2e3e8, bucket_name: datapipeline, object_name: data/database.csv; 20475)
[2024-05-10T07:29:28.222+0000] {local_task_job_runner.py:240} INFO - Task exited with return code 1
[2024-05-10T07:29:28.239+0000] {taskinstance.py:3498} INFO - 0 downstream tasks scheduled from follow-on schedule check
[2024-05-10T07:29:28.241+0000] {local_task_job_runner.py:222} INFO - ::endgroup::
