[2024-05-09T17:21:30.935+0000] {local_task_job_runner.py:120} INFO - ::group::Pre task execution logs
[2024-05-09T17:21:30.987+0000] {taskinstance.py:2076} INFO - Dependencies all met for dep_context=non-requeueable deps ti=<TaskInstance: ml_pipeline.get_api_data manual__2024-05-09T17:07:14.576867+00:00 [queued]>
[2024-05-09T17:21:31.003+0000] {taskinstance.py:2076} INFO - Dependencies all met for dep_context=requeueable deps ti=<TaskInstance: ml_pipeline.get_api_data manual__2024-05-09T17:07:14.576867+00:00 [queued]>
[2024-05-09T17:21:31.013+0000] {taskinstance.py:2306} INFO - Starting attempt 13 of 16
[2024-05-09T17:21:31.037+0000] {taskinstance.py:2330} INFO - Executing <Task(PythonOperator): get_api_data> on 2024-05-09 17:07:14.576867+00:00
[2024-05-09T17:21:31.051+0000] {logging_mixin.py:188} WARNING - /home/***/.local/lib/python3.12/site-packages/***/task/task_runner/standard_task_runner.py:61 DeprecationWarning: This process (pid=390) is multi-threaded, use of fork() may lead to deadlocks in the child.
[2024-05-09T17:21:31.053+0000] {standard_task_runner.py:63} INFO - Started process 392 to run task
[2024-05-09T17:21:31.051+0000] {standard_task_runner.py:90} INFO - Running: ['***', 'tasks', 'run', 'ml_pipeline', 'get_api_data', 'manual__2024-05-09T17:07:14.576867+00:00', '--job-id', '67', '--raw', '--subdir', 'DAGS_FOLDER/main_dag.py', '--cfg-path', '/tmp/tmpe65lgbs2']
[2024-05-09T17:21:31.055+0000] {standard_task_runner.py:91} INFO - Job 67: Subtask get_api_data
[2024-05-09T17:21:31.106+0000] {logging_mixin.py:188} WARNING - /home/***/.local/lib/python3.12/site-packages/***/settings.py:195 DeprecationWarning: The sql_alchemy_conn option in [core] has been moved to the sql_alchemy_conn option in [database] - the old setting has been used, but please update your config.
[2024-05-09T17:21:31.170+0000] {task_command.py:426} INFO - Running <TaskInstance: ml_pipeline.get_api_data manual__2024-05-09T17:07:14.576867+00:00 [running]> on host 2e12adb076a9
[2024-05-09T17:21:31.306+0000] {taskinstance.py:2648} INFO - Exporting env vars: AIRFLOW_CTX_DAG_OWNER='***' AIRFLOW_CTX_DAG_ID='ml_pipeline' AIRFLOW_CTX_TASK_ID='get_api_data' AIRFLOW_CTX_EXECUTION_DATE='2024-05-09T17:07:14.576867+00:00' AIRFLOW_CTX_TRY_NUMBER='13' AIRFLOW_CTX_DAG_RUN_ID='manual__2024-05-09T17:07:14.576867+00:00'
[2024-05-09T17:21:31.312+0000] {taskinstance.py:430} INFO - ::endgroup::
[2024-05-09T17:21:32.734+0000] {logging_mixin.py:188} INFO - Retrieved data for page 0
[2024-05-09T17:21:32.737+0000] {logging_mixin.py:188} INFO - Retrieved DOIs
[2024-05-09T17:21:33.401+0000] {logging_mixin.py:188} INFO - Retrieved data for DOI 0
[2024-05-09T17:21:33.402+0000] {taskinstance.py:441} INFO - ::group::Post task execution logs
[2024-05-09T17:21:33.403+0000] {taskinstance.py:2905} ERROR - Task failed with exception
Traceback (most recent call last):
  File "/home/airflow/.local/lib/python3.12/site-packages/airflow/models/taskinstance.py", line 465, in _execute_task
    result = _execute_callable(context=context, **execute_callable_kwargs)
             ^^^^^^^^^^^^^^^^^^^^^^^^^^^^^^^^^^^^^^^^^^^^^^^^^^^^^^^^^^^^^
  File "/home/airflow/.local/lib/python3.12/site-packages/airflow/models/taskinstance.py", line 432, in _execute_callable
    return execute_callable(context=context, **execute_callable_kwargs)
           ^^^^^^^^^^^^^^^^^^^^^^^^^^^^^^^^^^^^^^^^^^^^^^^^^^^^^^^^^^^^
  File "/home/airflow/.local/lib/python3.12/site-packages/airflow/models/baseoperator.py", line 400, in wrapper
    return func(self, *args, **kwargs)
           ^^^^^^^^^^^^^^^^^^^^^^^^^^^
  File "/home/airflow/.local/lib/python3.12/site-packages/airflow/operators/python.py", line 235, in execute
    return_value = self.execute_callable()
                   ^^^^^^^^^^^^^^^^^^^^^^^
  File "/home/airflow/.local/lib/python3.12/site-packages/airflow/operators/python.py", line 252, in execute_callable
    return self.python_callable(*self.op_args, **self.op_kwargs)
           ^^^^^^^^^^^^^^^^^^^^^^^^^^^^^^^^^^^^^^^^^^^^^^^^^^^^^
  File "/opt/airflow/dags/tasks/get_api_data.py", line 49, in get_api_data
    with open(file_path, 'w') as f:
         ^^^^^^^^^^^^^^^^^^^^
FileNotFoundError: [Errno 2] No such file or directory: 'airflow_data/api_data_json/research_0.json'
[2024-05-09T17:21:33.449+0000] {taskinstance.py:1206} INFO - Marking task as UP_FOR_RETRY. dag_id=ml_pipeline, task_id=get_api_data, run_id=manual__2024-05-09T17:07:14.576867+00:00, execution_date=20240509T170714, start_date=20240509T172130, end_date=20240509T172133
[2024-05-09T17:21:33.469+0000] {standard_task_runner.py:110} ERROR - Failed to execute job 67 for task get_api_data ([Errno 2] No such file or directory: 'airflow_data/api_data_json/research_0.json'; 392)
[2024-05-09T17:21:33.518+0000] {local_task_job_runner.py:240} INFO - Task exited with return code 1
[2024-05-09T17:21:33.551+0000] {taskinstance.py:3498} INFO - 0 downstream tasks scheduled from follow-on schedule check
[2024-05-09T17:21:33.554+0000] {local_task_job_runner.py:222} INFO - ::endgroup::
