[2024-05-09T16:38:00.873+0000] {local_task_job_runner.py:120} INFO - ::group::Pre task execution logs
[2024-05-09T16:38:00.896+0000] {taskinstance.py:2076} INFO - Dependencies all met for dep_context=non-requeueable deps ti=<TaskInstance: ml_pipeline.data_to_csv manual__2024-05-09T16:37:59.423037+00:00 [queued]>
[2024-05-09T16:38:00.904+0000] {taskinstance.py:2076} INFO - Dependencies all met for dep_context=requeueable deps ti=<TaskInstance: ml_pipeline.data_to_csv manual__2024-05-09T16:37:59.423037+00:00 [queued]>
[2024-05-09T16:38:00.905+0000] {taskinstance.py:2306} INFO - Starting attempt 1 of 4
[2024-05-09T16:38:00.916+0000] {taskinstance.py:2330} INFO - Executing <Task(PythonOperator): data_to_csv> on 2024-05-09 16:37:59.423037+00:00
[2024-05-09T16:38:00.924+0000] {logging_mixin.py:188} WARNING - /home/***/.local/lib/python3.12/site-packages/***/task/task_runner/standard_task_runner.py:61 DeprecationWarning: This process (pid=732) is multi-threaded, use of fork() may lead to deadlocks in the child.
[2024-05-09T16:38:00.924+0000] {standard_task_runner.py:90} INFO - Running: ['***', 'tasks', 'run', 'ml_pipeline', 'data_to_csv', 'manual__2024-05-09T16:37:59.423037+00:00', '--job-id', '39', '--raw', '--subdir', 'DAGS_FOLDER/main_dag.py', '--cfg-path', '/tmp/tmpdovqrse8']
[2024-05-09T16:38:00.925+0000] {standard_task_runner.py:63} INFO - Started process 737 to run task
[2024-05-09T16:38:00.926+0000] {standard_task_runner.py:91} INFO - Job 39: Subtask data_to_csv
[2024-05-09T16:38:00.939+0000] {logging_mixin.py:188} WARNING - /home/***/.local/lib/python3.12/site-packages/***/settings.py:195 DeprecationWarning: The sql_alchemy_conn option in [core] has been moved to the sql_alchemy_conn option in [database] - the old setting has been used, but please update your config.
[2024-05-09T16:38:00.970+0000] {task_command.py:426} INFO - Running <TaskInstance: ml_pipeline.data_to_csv manual__2024-05-09T16:37:59.423037+00:00 [running]> on host c78fa7b1ea7a
[2024-05-09T16:38:01.048+0000] {taskinstance.py:2648} INFO - Exporting env vars: AIRFLOW_CTX_DAG_OWNER='***' AIRFLOW_CTX_DAG_ID='ml_pipeline' AIRFLOW_CTX_TASK_ID='data_to_csv' AIRFLOW_CTX_EXECUTION_DATE='2024-05-09T16:37:59.423037+00:00' AIRFLOW_CTX_TRY_NUMBER='1' AIRFLOW_CTX_DAG_RUN_ID='manual__2024-05-09T16:37:59.423037+00:00'
[2024-05-09T16:38:01.050+0000] {taskinstance.py:430} INFO - ::endgroup::
[2024-05-09T16:38:01.066+0000] {connectionpool.py:874} WARNING - Retrying (Retry(total=4, connect=None, read=None, redirect=None, status=None)) after connection broken by 'NewConnectionError('<urllib3.connection.HTTPConnection object at 0x7f5f156526c0>: Failed to establish a new connection: [Errno 111] Connection refused')': /datapipeline?location=
[2024-05-09T16:38:01.467+0000] {connectionpool.py:874} WARNING - Retrying (Retry(total=3, connect=None, read=None, redirect=None, status=None)) after connection broken by 'NewConnectionError('<urllib3.connection.HTTPConnection object at 0x7f5ef4f6f9b0>: Failed to establish a new connection: [Errno 111] Connection refused')': /datapipeline?location=
[2024-05-09T16:38:02.270+0000] {connectionpool.py:874} WARNING - Retrying (Retry(total=2, connect=None, read=None, redirect=None, status=None)) after connection broken by 'NewConnectionError('<urllib3.connection.HTTPConnection object at 0x7f5ef4f6fc20>: Failed to establish a new connection: [Errno 111] Connection refused')': /datapipeline?location=
[2024-05-09T16:38:03.871+0000] {connectionpool.py:874} WARNING - Retrying (Retry(total=1, connect=None, read=None, redirect=None, status=None)) after connection broken by 'NewConnectionError('<urllib3.connection.HTTPConnection object at 0x7f5ef4f9c170>: Failed to establish a new connection: [Errno 111] Connection refused')': /datapipeline?location=
[2024-05-09T16:38:07.073+0000] {connectionpool.py:874} WARNING - Retrying (Retry(total=0, connect=None, read=None, redirect=None, status=None)) after connection broken by 'NewConnectionError('<urllib3.connection.HTTPConnection object at 0x7f5ef4f9c710>: Failed to establish a new connection: [Errno 111] Connection refused')': /datapipeline?location=
[2024-05-09T16:38:07.076+0000] {taskinstance.py:441} INFO - ::group::Post task execution logs
[2024-05-09T16:38:07.077+0000] {taskinstance.py:2905} ERROR - Task failed with exception
Traceback (most recent call last):
  File "/home/airflow/.local/lib/python3.12/site-packages/urllib3/connection.py", line 198, in _new_conn
    sock = connection.create_connection(
           ^^^^^^^^^^^^^^^^^^^^^^^^^^^^^
  File "/home/airflow/.local/lib/python3.12/site-packages/urllib3/util/connection.py", line 85, in create_connection
    raise err
  File "/home/airflow/.local/lib/python3.12/site-packages/urllib3/util/connection.py", line 73, in create_connection
    sock.connect(sa)
ConnectionRefusedError: [Errno 111] Connection refused

The above exception was the direct cause of the following exception:

Traceback (most recent call last):
  File "/home/airflow/.local/lib/python3.12/site-packages/urllib3/connectionpool.py", line 793, in urlopen
    response = self._make_request(
               ^^^^^^^^^^^^^^^^^^^
  File "/home/airflow/.local/lib/python3.12/site-packages/urllib3/connectionpool.py", line 496, in _make_request
    conn.request(
  File "/home/airflow/.local/lib/python3.12/site-packages/urllib3/connection.py", line 400, in request
    self.endheaders()
  File "/usr/local/lib/python3.12/http/client.py", line 1331, in endheaders
    self._send_output(message_body, encode_chunked=encode_chunked)
  File "/usr/local/lib/python3.12/http/client.py", line 1091, in _send_output
    self.send(msg)
  File "/usr/local/lib/python3.12/http/client.py", line 1035, in send
    self.connect()
  File "/home/airflow/.local/lib/python3.12/site-packages/urllib3/connection.py", line 238, in connect
    self.sock = self._new_conn()
                ^^^^^^^^^^^^^^^^
  File "/home/airflow/.local/lib/python3.12/site-packages/urllib3/connection.py", line 213, in _new_conn
    raise NewConnectionError(
urllib3.exceptions.NewConnectionError: <urllib3.connection.HTTPConnection object at 0x7f5ef4f9c530>: Failed to establish a new connection: [Errno 111] Connection refused

The above exception was the direct cause of the following exception:

Traceback (most recent call last):
  File "/home/airflow/.local/lib/python3.12/site-packages/airflow/models/taskinstance.py", line 465, in _execute_task
    result = _execute_callable(context=context, **execute_callable_kwargs)
             ^^^^^^^^^^^^^^^^^^^^^^^^^^^^^^^^^^^^^^^^^^^^^^^^^^^^^^^^^^^^^
  File "/home/airflow/.local/lib/python3.12/site-packages/airflow/models/taskinstance.py", line 432, in _execute_callable
    return execute_callable(context=context, **execute_callable_kwargs)
           ^^^^^^^^^^^^^^^^^^^^^^^^^^^^^^^^^^^^^^^^^^^^^^^^^^^^^^^^^^^^
  File "/home/airflow/.local/lib/python3.12/site-packages/airflow/models/baseoperator.py", line 400, in wrapper
    return func(self, *args, **kwargs)
           ^^^^^^^^^^^^^^^^^^^^^^^^^^^
  File "/home/airflow/.local/lib/python3.12/site-packages/airflow/operators/python.py", line 235, in execute
    return_value = self.execute_callable()
                   ^^^^^^^^^^^^^^^^^^^^^^^
  File "/home/airflow/.local/lib/python3.12/site-packages/airflow/operators/python.py", line 252, in execute_callable
    return self.python_callable(*self.op_args, **self.op_kwargs)
           ^^^^^^^^^^^^^^^^^^^^^^^^^^^^^^^^^^^^^^^^^^^^^^^^^^^^^
  File "/opt/airflow/dags/tasks/extract_data.py", line 99, in extract_api_data
    for obj in minio_client.list_objects(bucket_name, prefix='data/api_data_json/'):
  File "/home/airflow/.local/lib/python3.12/site-packages/minio/api.py", line 3109, in _list_objects
    response = self._execute(
               ^^^^^^^^^^^^^^
  File "/home/airflow/.local/lib/python3.12/site-packages/minio/api.py", line 437, in _execute
    region = self._get_region(bucket_name)
             ^^^^^^^^^^^^^^^^^^^^^^^^^^^^^
  File "/home/airflow/.local/lib/python3.12/site-packages/minio/api.py", line 494, in _get_region
    response = self._url_open(
               ^^^^^^^^^^^^^^^
  File "/home/airflow/.local/lib/python3.12/site-packages/minio/api.py", line 302, in _url_open
    response = self._http.urlopen(
               ^^^^^^^^^^^^^^^^^^^
  File "/home/airflow/.local/lib/python3.12/site-packages/urllib3/poolmanager.py", line 444, in urlopen
    response = conn.urlopen(method, u.request_uri, **kw)
               ^^^^^^^^^^^^^^^^^^^^^^^^^^^^^^^^^^^^^^^^^
  File "/home/airflow/.local/lib/python3.12/site-packages/urllib3/connectionpool.py", line 877, in urlopen
    return self.urlopen(
           ^^^^^^^^^^^^^
  File "/home/airflow/.local/lib/python3.12/site-packages/urllib3/connectionpool.py", line 877, in urlopen
    return self.urlopen(
           ^^^^^^^^^^^^^
  File "/home/airflow/.local/lib/python3.12/site-packages/urllib3/connectionpool.py", line 877, in urlopen
    return self.urlopen(
           ^^^^^^^^^^^^^
  [Previous line repeated 2 more times]
  File "/home/airflow/.local/lib/python3.12/site-packages/urllib3/connectionpool.py", line 847, in urlopen
    retries = retries.increment(
              ^^^^^^^^^^^^^^^^^^
  File "/home/airflow/.local/lib/python3.12/site-packages/urllib3/util/retry.py", line 515, in increment
    raise MaxRetryError(_pool, url, reason) from reason  # type: ignore[arg-type]
    ^^^^^^^^^^^^^^^^^^^^^^^^^^^^^^^^^^^^^^^^^^^^^^^^^^^
urllib3.exceptions.MaxRetryError: HTTPConnectionPool(host='localhost', port=9000): Max retries exceeded with url: /datapipeline?location= (Caused by NewConnectionError('<urllib3.connection.HTTPConnection object at 0x7f5ef4f9c530>: Failed to establish a new connection: [Errno 111] Connection refused'))
[2024-05-09T16:38:07.137+0000] {taskinstance.py:1206} INFO - Marking task as UP_FOR_RETRY. dag_id=ml_pipeline, task_id=data_to_csv, run_id=manual__2024-05-09T16:37:59.423037+00:00, execution_date=20240509T163759, start_date=20240509T163800, end_date=20240509T163807
[2024-05-09T16:38:07.189+0000] {standard_task_runner.py:110} ERROR - Failed to execute job 39 for task data_to_csv (HTTPConnectionPool(host='localhost', port=9000): Max retries exceeded with url: /datapipeline?location= (Caused by NewConnectionError('<urllib3.connection.HTTPConnection object at 0x7f5ef4f9c530>: Failed to establish a new connection: [Errno 111] Connection refused')); 737)
[2024-05-09T16:38:07.247+0000] {local_task_job_runner.py:240} INFO - Task exited with return code 1
[2024-05-09T16:38:07.311+0000] {taskinstance.py:3498} INFO - 0 downstream tasks scheduled from follow-on schedule check
[2024-05-09T16:38:07.322+0000] {local_task_job_runner.py:222} INFO - ::endgroup::
