[2024-05-09T16:35:06.353+0000] {local_task_job_runner.py:120} INFO - ::group::Pre task execution logs
[2024-05-09T16:35:06.378+0000] {taskinstance.py:2076} INFO - Dependencies all met for dep_context=non-requeueable deps ti=<TaskInstance: ml_pipeline.get_api_data manual__2024-05-09T16:23:09.223600+00:00 [queued]>
[2024-05-09T16:35:06.386+0000] {taskinstance.py:2076} INFO - Dependencies all met for dep_context=requeueable deps ti=<TaskInstance: ml_pipeline.get_api_data manual__2024-05-09T16:23:09.223600+00:00 [queued]>
[2024-05-09T16:35:06.387+0000] {taskinstance.py:2306} INFO - Starting attempt 6 of 9
[2024-05-09T16:35:06.399+0000] {taskinstance.py:2330} INFO - Executing <Task(PythonOperator): get_api_data> on 2024-05-09 16:23:09.223600+00:00
[2024-05-09T16:35:06.406+0000] {logging_mixin.py:188} WARNING - /home/***/.local/lib/python3.12/site-packages/***/task/task_runner/standard_task_runner.py:61 DeprecationWarning: This process (pid=602) is multi-threaded, use of fork() may lead to deadlocks in the child.
[2024-05-09T16:35:06.407+0000] {standard_task_runner.py:63} INFO - Started process 607 to run task
[2024-05-09T16:35:06.405+0000] {standard_task_runner.py:90} INFO - Running: ['***', 'tasks', 'run', 'ml_pipeline', 'get_api_data', 'manual__2024-05-09T16:23:09.223600+00:00', '--job-id', '31', '--raw', '--subdir', 'DAGS_FOLDER/main_dag.py', '--cfg-path', '/tmp/tmpz2qy5jy5']
[2024-05-09T16:35:06.408+0000] {standard_task_runner.py:91} INFO - Job 31: Subtask get_api_data
[2024-05-09T16:35:06.419+0000] {logging_mixin.py:188} WARNING - /home/***/.local/lib/python3.12/site-packages/***/settings.py:195 DeprecationWarning: The sql_alchemy_conn option in [core] has been moved to the sql_alchemy_conn option in [database] - the old setting has been used, but please update your config.
[2024-05-09T16:35:06.450+0000] {task_command.py:426} INFO - Running <TaskInstance: ml_pipeline.get_api_data manual__2024-05-09T16:23:09.223600+00:00 [running]> on host c78fa7b1ea7a
[2024-05-09T16:35:06.524+0000] {taskinstance.py:2648} INFO - Exporting env vars: AIRFLOW_CTX_DAG_OWNER='***' AIRFLOW_CTX_DAG_ID='ml_pipeline' AIRFLOW_CTX_TASK_ID='get_api_data' AIRFLOW_CTX_EXECUTION_DATE='2024-05-09T16:23:09.223600+00:00' AIRFLOW_CTX_TRY_NUMBER='6' AIRFLOW_CTX_DAG_RUN_ID='manual__2024-05-09T16:23:09.223600+00:00'
[2024-05-09T16:35:06.525+0000] {taskinstance.py:430} INFO - ::endgroup::
[2024-05-09T16:35:09.788+0000] {logging_mixin.py:188} INFO - Retrieved data for page 0
[2024-05-09T16:35:09.790+0000] {logging_mixin.py:188} INFO - Retrieved DOIs
[2024-05-09T16:35:10.851+0000] {logging_mixin.py:188} INFO - Retrieved data for DOI 0
[2024-05-09T16:35:10.855+0000] {taskinstance.py:441} INFO - ::group::Post task execution logs
[2024-05-09T16:35:10.858+0000] {taskinstance.py:2905} ERROR - Task failed with exception
Traceback (most recent call last):
  File "/home/airflow/.local/lib/python3.12/site-packages/airflow/models/taskinstance.py", line 465, in _execute_task
    result = _execute_callable(context=context, **execute_callable_kwargs)
             ^^^^^^^^^^^^^^^^^^^^^^^^^^^^^^^^^^^^^^^^^^^^^^^^^^^^^^^^^^^^^
  File "/home/airflow/.local/lib/python3.12/site-packages/airflow/models/taskinstance.py", line 432, in _execute_callable
    return execute_callable(context=context, **execute_callable_kwargs)
           ^^^^^^^^^^^^^^^^^^^^^^^^^^^^^^^^^^^^^^^^^^^^^^^^^^^^^^^^^^^^
  File "/home/airflow/.local/lib/python3.12/site-packages/airflow/models/baseoperator.py", line 400, in wrapper
    return func(self, *args, **kwargs)
           ^^^^^^^^^^^^^^^^^^^^^^^^^^^
  File "/home/airflow/.local/lib/python3.12/site-packages/airflow/operators/python.py", line 235, in execute
    return_value = self.execute_callable()
                   ^^^^^^^^^^^^^^^^^^^^^^^
  File "/home/airflow/.local/lib/python3.12/site-packages/airflow/operators/python.py", line 252, in execute_callable
    return self.python_callable(*self.op_args, **self.op_kwargs)
           ^^^^^^^^^^^^^^^^^^^^^^^^^^^^^^^^^^^^^^^^^^^^^^^^^^^^^
  File "/opt/airflow/dags/tasks/get_api_data.py", line 50, in get_api_data
    with open(file_path, 'w') as f:
         ^^^^^^^^^^^^^^^^^^^^
FileNotFoundError: [Errno 2] No such file or directory: 'airflow_data/api_data_json/research_0.json'
[2024-05-09T16:35:10.929+0000] {taskinstance.py:1206} INFO - Marking task as UP_FOR_RETRY. dag_id=ml_pipeline, task_id=get_api_data, run_id=manual__2024-05-09T16:23:09.223600+00:00, execution_date=20240509T162309, start_date=20240509T163506, end_date=20240509T163510
[2024-05-09T16:35:10.981+0000] {standard_task_runner.py:110} ERROR - Failed to execute job 31 for task get_api_data ([Errno 2] No such file or directory: 'airflow_data/api_data_json/research_0.json'; 607)
[2024-05-09T16:35:11.008+0000] {local_task_job_runner.py:240} INFO - Task exited with return code 1
[2024-05-09T16:35:11.029+0000] {taskinstance.py:3498} INFO - 0 downstream tasks scheduled from follow-on schedule check
[2024-05-09T16:35:11.031+0000] {local_task_job_runner.py:222} INFO - ::endgroup::
