[2024-05-10T10:37:57.171+0000] {local_task_job_runner.py:120} INFO - ::group::Pre task execution logs
[2024-05-10T10:37:57.200+0000] {taskinstance.py:2076} INFO - Dependencies all met for dep_context=non-requeueable deps ti=<TaskInstance: data_pipeline.divide_data manual__2024-05-10T10:18:14.377791+00:00 [queued]>
[2024-05-10T10:37:57.210+0000] {taskinstance.py:2076} INFO - Dependencies all met for dep_context=requeueable deps ti=<TaskInstance: data_pipeline.divide_data manual__2024-05-10T10:18:14.377791+00:00 [queued]>
[2024-05-10T10:37:57.210+0000] {taskinstance.py:2306} INFO - Starting attempt 3 of 6
[2024-05-10T10:37:57.224+0000] {taskinstance.py:2330} INFO - Executing <Task(PythonOperator): divide_data> on 2024-05-10 10:18:14.377791+00:00
[2024-05-10T10:37:57.230+0000] {logging_mixin.py:188} WARNING - /home/***/.local/lib/python3.12/site-packages/***/task/task_runner/standard_task_runner.py:61 DeprecationWarning: This process (pid=1703) is multi-threaded, use of fork() may lead to deadlocks in the child.
[2024-05-10T10:37:57.232+0000] {standard_task_runner.py:63} INFO - Started process 1705 to run task
[2024-05-10T10:37:57.230+0000] {standard_task_runner.py:90} INFO - Running: ['***', 'tasks', 'run', 'data_pipeline', 'divide_data', 'manual__2024-05-10T10:18:14.377791+00:00', '--job-id', '384', '--raw', '--subdir', 'DAGS_FOLDER/main_dag.py', '--cfg-path', '/tmp/tmpcj8ylx4j']
[2024-05-10T10:37:57.233+0000] {standard_task_runner.py:91} INFO - Job 384: Subtask divide_data
[2024-05-10T10:37:57.243+0000] {logging_mixin.py:188} WARNING - /home/***/.local/lib/python3.12/site-packages/***/settings.py:195 DeprecationWarning: The sql_alchemy_conn option in [core] has been moved to the sql_alchemy_conn option in [database] - the old setting has been used, but please update your config.
[2024-05-10T10:37:57.271+0000] {task_command.py:426} INFO - Running <TaskInstance: data_pipeline.divide_data manual__2024-05-10T10:18:14.377791+00:00 [running]> on host dbfcb70dcca2
[2024-05-10T10:37:57.340+0000] {taskinstance.py:2648} INFO - Exporting env vars: AIRFLOW_CTX_DAG_OWNER='***' AIRFLOW_CTX_DAG_ID='data_pipeline' AIRFLOW_CTX_TASK_ID='divide_data' AIRFLOW_CTX_EXECUTION_DATE='2024-05-10T10:18:14.377791+00:00' AIRFLOW_CTX_TRY_NUMBER='3' AIRFLOW_CTX_DAG_RUN_ID='manual__2024-05-10T10:18:14.377791+00:00'
[2024-05-10T10:37:57.341+0000] {taskinstance.py:430} INFO - ::endgroup::
[2024-05-10T10:37:57.942+0000] {taskinstance.py:441} INFO - ::group::Post task execution logs
[2024-05-10T10:37:57.943+0000] {taskinstance.py:2905} ERROR - Task failed with exception
Traceback (most recent call last):
  File "/home/airflow/.local/lib/python3.12/site-packages/airflow/models/taskinstance.py", line 465, in _execute_task
    result = _execute_callable(context=context, **execute_callable_kwargs)
             ^^^^^^^^^^^^^^^^^^^^^^^^^^^^^^^^^^^^^^^^^^^^^^^^^^^^^^^^^^^^^
  File "/home/airflow/.local/lib/python3.12/site-packages/airflow/models/taskinstance.py", line 432, in _execute_callable
    return execute_callable(context=context, **execute_callable_kwargs)
           ^^^^^^^^^^^^^^^^^^^^^^^^^^^^^^^^^^^^^^^^^^^^^^^^^^^^^^^^^^^^
  File "/home/airflow/.local/lib/python3.12/site-packages/airflow/models/baseoperator.py", line 400, in wrapper
    return func(self, *args, **kwargs)
           ^^^^^^^^^^^^^^^^^^^^^^^^^^^
  File "/home/airflow/.local/lib/python3.12/site-packages/airflow/operators/python.py", line 235, in execute
    return_value = self.execute_callable()
                   ^^^^^^^^^^^^^^^^^^^^^^^
  File "/home/airflow/.local/lib/python3.12/site-packages/airflow/operators/python.py", line 252, in execute_callable
    return self.python_callable(*self.op_args, **self.op_kwargs)
           ^^^^^^^^^^^^^^^^^^^^^^^^^^^^^^^^^^^^^^^^^^^^^^^^^^^^^
  File "/opt/airflow/dags/tasks/divide_data.py", line 27, in divide_data
    title_keywords_year(df)
  File "/opt/airflow/dags/tasks/divide_data.py", line 52, in title_keywords_year
    new_df.to_csv('airflow_data/title_keywords.csv', index=False)
  File "/home/airflow/.local/lib/python3.12/site-packages/pandas/core/generic.py", line 3902, in to_csv
    return DataFrameRenderer(formatter).to_csv(
           ^^^^^^^^^^^^^^^^^^^^^^^^^^^^^^^^^^^^
  File "/home/airflow/.local/lib/python3.12/site-packages/pandas/io/formats/format.py", line 1152, in to_csv
    csv_formatter.save()
  File "/home/airflow/.local/lib/python3.12/site-packages/pandas/io/formats/csvs.py", line 247, in save
    with get_handle(
         ^^^^^^^^^^^
  File "/home/airflow/.local/lib/python3.12/site-packages/pandas/io/common.py", line 739, in get_handle
    check_parent_directory(str(handle))
  File "/home/airflow/.local/lib/python3.12/site-packages/pandas/io/common.py", line 604, in check_parent_directory
    raise OSError(rf"Cannot save file into a non-existent directory: '{parent}'")
OSError: Cannot save file into a non-existent directory: '***_data'
[2024-05-10T10:37:57.961+0000] {taskinstance.py:1206} INFO - Marking task as UP_FOR_RETRY. dag_id=data_pipeline, task_id=divide_data, run_id=manual__2024-05-10T10:18:14.377791+00:00, execution_date=20240510T101814, start_date=20240510T103757, end_date=20240510T103757
[2024-05-10T10:37:57.972+0000] {standard_task_runner.py:110} ERROR - Failed to execute job 384 for task divide_data (Cannot save file into a non-existent directory: '***_data'; 1705)
[2024-05-10T10:37:58.007+0000] {local_task_job_runner.py:240} INFO - Task exited with return code 1
[2024-05-10T10:37:58.025+0000] {taskinstance.py:3498} INFO - 0 downstream tasks scheduled from follow-on schedule check
[2024-05-10T10:37:58.027+0000] {local_task_job_runner.py:222} INFO - ::endgroup::
