[2024-05-10T13:36:23.709+0000] {local_task_job_runner.py:120} INFO - ::group::Pre task execution logs
[2024-05-10T13:36:23.731+0000] {taskinstance.py:2076} INFO - Dependencies all met for dep_context=non-requeueable deps ti=<TaskInstance: data_pipeline.divide_data manual__2024-05-10T10:18:14.377791+00:00 [queued]>
[2024-05-10T13:36:23.737+0000] {taskinstance.py:2076} INFO - Dependencies all met for dep_context=requeueable deps ti=<TaskInstance: data_pipeline.divide_data manual__2024-05-10T10:18:14.377791+00:00 [queued]>
[2024-05-10T13:36:23.738+0000] {taskinstance.py:2306} INFO - Starting attempt 124 of 127
[2024-05-10T13:36:23.748+0000] {taskinstance.py:2330} INFO - Executing <Task(PythonOperator): divide_data> on 2024-05-10 10:18:14.377791+00:00
[2024-05-10T13:36:23.754+0000] {logging_mixin.py:188} WARNING - /home/***/.local/lib/python3.12/site-packages/***/task/task_runner/standard_task_runner.py:61 DeprecationWarning: This process (pid=9690) is multi-threaded, use of fork() may lead to deadlocks in the child.
[2024-05-10T13:36:23.755+0000] {standard_task_runner.py:63} INFO - Started process 9692 to run task
[2024-05-10T13:36:23.754+0000] {standard_task_runner.py:90} INFO - Running: ['***', 'tasks', 'run', 'data_pipeline', 'divide_data', 'manual__2024-05-10T10:18:14.377791+00:00', '--job-id', '553', '--raw', '--subdir', 'DAGS_FOLDER/main_dag.py', '--cfg-path', '/tmp/tmp5z05p6ii']
[2024-05-10T13:36:23.756+0000] {standard_task_runner.py:91} INFO - Job 553: Subtask divide_data
[2024-05-10T13:36:23.766+0000] {logging_mixin.py:188} WARNING - /home/***/.local/lib/python3.12/site-packages/***/settings.py:195 DeprecationWarning: The sql_alchemy_conn option in [core] has been moved to the sql_alchemy_conn option in [database] - the old setting has been used, but please update your config.
[2024-05-10T13:36:23.791+0000] {task_command.py:426} INFO - Running <TaskInstance: data_pipeline.divide_data manual__2024-05-10T10:18:14.377791+00:00 [running]> on host dbfcb70dcca2
[2024-05-10T13:36:23.855+0000] {taskinstance.py:2648} INFO - Exporting env vars: AIRFLOW_CTX_DAG_OWNER='***' AIRFLOW_CTX_DAG_ID='data_pipeline' AIRFLOW_CTX_TASK_ID='divide_data' AIRFLOW_CTX_EXECUTION_DATE='2024-05-10T10:18:14.377791+00:00' AIRFLOW_CTX_TRY_NUMBER='124' AIRFLOW_CTX_DAG_RUN_ID='manual__2024-05-10T10:18:14.377791+00:00'
[2024-05-10T13:36:23.856+0000] {taskinstance.py:430} INFO - ::endgroup::
[2024-05-10T13:36:28.445+0000] {taskinstance.py:441} INFO - ::group::Post task execution logs
[2024-05-10T13:36:28.446+0000] {taskinstance.py:2905} ERROR - Task failed with exception
Traceback (most recent call last):
  File "/home/airflow/.local/lib/python3.12/site-packages/airflow/models/taskinstance.py", line 465, in _execute_task
    result = _execute_callable(context=context, **execute_callable_kwargs)
             ^^^^^^^^^^^^^^^^^^^^^^^^^^^^^^^^^^^^^^^^^^^^^^^^^^^^^^^^^^^^^
  File "/home/airflow/.local/lib/python3.12/site-packages/airflow/models/taskinstance.py", line 432, in _execute_callable
    return execute_callable(context=context, **execute_callable_kwargs)
           ^^^^^^^^^^^^^^^^^^^^^^^^^^^^^^^^^^^^^^^^^^^^^^^^^^^^^^^^^^^^
  File "/home/airflow/.local/lib/python3.12/site-packages/airflow/models/baseoperator.py", line 400, in wrapper
    return func(self, *args, **kwargs)
           ^^^^^^^^^^^^^^^^^^^^^^^^^^^
  File "/home/airflow/.local/lib/python3.12/site-packages/airflow/operators/python.py", line 235, in execute
    return_value = self.execute_callable()
                   ^^^^^^^^^^^^^^^^^^^^^^^
  File "/home/airflow/.local/lib/python3.12/site-packages/airflow/operators/python.py", line 252, in execute_callable
    return self.python_callable(*self.op_args, **self.op_kwargs)
           ^^^^^^^^^^^^^^^^^^^^^^^^^^^^^^^^^^^^^^^^^^^^^^^^^^^^^
  File "/opt/airflow/dags/tasks/divide_data.py", line 36, in divide_data
    title_affiliation(df, file_path_to_upload)
  File "/opt/airflow/dags/tasks/divide_data.py", line 91, in title_affiliation
    df_expanded = df.explode(['affiliation_name', 'affiliation_country'])
                  ^^^^^^^^^^^^^^^^^^^^^^^^^^^^^^^^^^^^^^^^^^^^^^^^^^^^^^^
  File "/home/airflow/.local/lib/python3.12/site-packages/pandas/core/frame.py", line 9546, in explode
    raise ValueError("columns must have matching element counts")
ValueError: columns must have matching element counts
[2024-05-10T13:36:28.458+0000] {taskinstance.py:1206} INFO - Marking task as UP_FOR_RETRY. dag_id=data_pipeline, task_id=divide_data, run_id=manual__2024-05-10T10:18:14.377791+00:00, execution_date=20240510T101814, start_date=20240510T133623, end_date=20240510T133628
[2024-05-10T13:36:28.466+0000] {standard_task_runner.py:110} ERROR - Failed to execute job 553 for task divide_data (columns must have matching element counts; 9692)
[2024-05-10T13:36:28.503+0000] {local_task_job_runner.py:240} INFO - Task exited with return code 1
[2024-05-10T13:36:28.524+0000] {taskinstance.py:3498} INFO - 0 downstream tasks scheduled from follow-on schedule check
[2024-05-10T13:36:28.526+0000] {local_task_job_runner.py:222} INFO - ::endgroup::
