[2024-05-10T10:35:32.028+0000] {task_context_logger.py:104} ERROR - Executor reports task instance <TaskInstance: data_pipeline.divide_data manual__2024-05-10T10:18:14.377791+00:00 [queued]> finished (success) although the task says it's queued. (Info: None) Was the task killed externally?
