[2024-05-10T10:35:46.886+0000] {local_task_job_runner.py:120} INFO - ::group::Pre task execution logs
[2024-05-10T10:35:46.917+0000] {taskinstance.py:2076} INFO - Dependencies all met for dep_context=non-requeueable deps ti=<TaskInstance: data_pipeline.divide_data manual__2024-05-10T10:18:14.377791+00:00 [queued]>
[2024-05-10T10:35:46.923+0000] {taskinstance.py:2076} INFO - Dependencies all met for dep_context=requeueable deps ti=<TaskInstance: data_pipeline.divide_data manual__2024-05-10T10:18:14.377791+00:00 [queued]>
[2024-05-10T10:35:46.924+0000] {taskinstance.py:2306} INFO - Starting attempt 2 of 5
[2024-05-10T10:35:46.934+0000] {taskinstance.py:2330} INFO - Executing <Task(PythonOperator): divide_data> on 2024-05-10 10:18:14.377791+00:00
[2024-05-10T10:35:46.939+0000] {logging_mixin.py:188} WARNING - /home/***/.local/lib/python3.12/site-packages/***/task/task_runner/standard_task_runner.py:61 DeprecationWarning: This process (pid=1634) is multi-threaded, use of fork() may lead to deadlocks in the child.
[2024-05-10T10:35:46.940+0000] {standard_task_runner.py:63} INFO - Started process 1636 to run task
[2024-05-10T10:35:46.939+0000] {standard_task_runner.py:90} INFO - Running: ['***', 'tasks', 'run', 'data_pipeline', 'divide_data', 'manual__2024-05-10T10:18:14.377791+00:00', '--job-id', '383', '--raw', '--subdir', 'DAGS_FOLDER/main_dag.py', '--cfg-path', '/tmp/tmpwrs6db5n']
[2024-05-10T10:35:46.941+0000] {standard_task_runner.py:91} INFO - Job 383: Subtask divide_data
[2024-05-10T10:35:46.951+0000] {logging_mixin.py:188} WARNING - /home/***/.local/lib/python3.12/site-packages/***/settings.py:195 DeprecationWarning: The sql_alchemy_conn option in [core] has been moved to the sql_alchemy_conn option in [database] - the old setting has been used, but please update your config.
[2024-05-10T10:35:46.974+0000] {task_command.py:426} INFO - Running <TaskInstance: data_pipeline.divide_data manual__2024-05-10T10:18:14.377791+00:00 [running]> on host dbfcb70dcca2
[2024-05-10T10:35:47.039+0000] {taskinstance.py:2648} INFO - Exporting env vars: AIRFLOW_CTX_DAG_OWNER='***' AIRFLOW_CTX_DAG_ID='data_pipeline' AIRFLOW_CTX_TASK_ID='divide_data' AIRFLOW_CTX_EXECUTION_DATE='2024-05-10T10:18:14.377791+00:00' AIRFLOW_CTX_TRY_NUMBER='2' AIRFLOW_CTX_DAG_RUN_ID='manual__2024-05-10T10:18:14.377791+00:00'
[2024-05-10T10:35:47.040+0000] {taskinstance.py:430} INFO - ::endgroup::
[2024-05-10T10:35:47.052+0000] {taskinstance.py:441} INFO - ::group::Post task execution logs
[2024-05-10T10:35:47.052+0000] {taskinstance.py:2905} ERROR - Task failed with exception
Traceback (most recent call last):
  File "/home/airflow/.local/lib/python3.12/site-packages/airflow/models/taskinstance.py", line 465, in _execute_task
    result = _execute_callable(context=context, **execute_callable_kwargs)
             ^^^^^^^^^^^^^^^^^^^^^^^^^^^^^^^^^^^^^^^^^^^^^^^^^^^^^^^^^^^^^
  File "/home/airflow/.local/lib/python3.12/site-packages/airflow/models/taskinstance.py", line 432, in _execute_callable
    return execute_callable(context=context, **execute_callable_kwargs)
           ^^^^^^^^^^^^^^^^^^^^^^^^^^^^^^^^^^^^^^^^^^^^^^^^^^^^^^^^^^^^
  File "/home/airflow/.local/lib/python3.12/site-packages/airflow/models/baseoperator.py", line 400, in wrapper
    return func(self, *args, **kwargs)
           ^^^^^^^^^^^^^^^^^^^^^^^^^^^
  File "/home/airflow/.local/lib/python3.12/site-packages/airflow/operators/python.py", line 235, in execute
    return_value = self.execute_callable()
                   ^^^^^^^^^^^^^^^^^^^^^^^
  File "/home/airflow/.local/lib/python3.12/site-packages/airflow/operators/python.py", line 252, in execute_callable
    return self.python_callable(*self.op_args, **self.op_kwargs)
           ^^^^^^^^^^^^^^^^^^^^^^^^^^^^^^^^^^^^^^^^^^^^^^^^^^^^^
  File "/opt/airflow/dags/tasks/divide_data.py", line 14, in divide_data
    df = pd.read_csv('airflow_data/database.csv')
         ^^^^^^^^^^^^^^^^^^^^^^^^^^^^^^^^^^^^^^^^
  File "/home/airflow/.local/lib/python3.12/site-packages/pandas/io/parsers/readers.py", line 948, in read_csv
    return _read(filepath_or_buffer, kwds)
           ^^^^^^^^^^^^^^^^^^^^^^^^^^^^^^^
  File "/home/airflow/.local/lib/python3.12/site-packages/pandas/io/parsers/readers.py", line 611, in _read
    parser = TextFileReader(filepath_or_buffer, **kwds)
             ^^^^^^^^^^^^^^^^^^^^^^^^^^^^^^^^^^^^^^^^^^
  File "/home/airflow/.local/lib/python3.12/site-packages/pandas/io/parsers/readers.py", line 1448, in __init__
    self._engine = self._make_engine(f, self.engine)
                   ^^^^^^^^^^^^^^^^^^^^^^^^^^^^^^^^^
  File "/home/airflow/.local/lib/python3.12/site-packages/pandas/io/parsers/readers.py", line 1705, in _make_engine
    self.handles = get_handle(
                   ^^^^^^^^^^^
  File "/home/airflow/.local/lib/python3.12/site-packages/pandas/io/common.py", line 863, in get_handle
    handle = open(
             ^^^^^
FileNotFoundError: [Errno 2] No such file or directory: 'airflow_data/database.csv'
[2024-05-10T10:35:47.064+0000] {taskinstance.py:1206} INFO - Marking task as UP_FOR_RETRY. dag_id=data_pipeline, task_id=divide_data, run_id=manual__2024-05-10T10:18:14.377791+00:00, execution_date=20240510T101814, start_date=20240510T103546, end_date=20240510T103547
[2024-05-10T10:35:47.072+0000] {standard_task_runner.py:110} ERROR - Failed to execute job 383 for task divide_data ([Errno 2] No such file or directory: 'airflow_data/database.csv'; 1636)
[2024-05-10T10:35:47.113+0000] {local_task_job_runner.py:240} INFO - Task exited with return code 1
[2024-05-10T10:35:47.129+0000] {taskinstance.py:3498} INFO - 0 downstream tasks scheduled from follow-on schedule check
[2024-05-10T10:35:47.131+0000] {local_task_job_runner.py:222} INFO - ::endgroup::
