[2024-05-10T14:17:51.890+0000] {local_task_job_runner.py:120} INFO - ::group::Pre task execution logs
[2024-05-10T14:17:51.913+0000] {taskinstance.py:2076} INFO - Dependencies all met for dep_context=non-requeueable deps ti=<TaskInstance: data_pipeline.divide_data manual__2024-05-10T10:18:14.377791+00:00 [queued]>
[2024-05-10T14:17:51.921+0000] {taskinstance.py:2076} INFO - Dependencies all met for dep_context=requeueable deps ti=<TaskInstance: data_pipeline.divide_data manual__2024-05-10T10:18:14.377791+00:00 [queued]>
[2024-05-10T14:17:51.921+0000] {taskinstance.py:2306} INFO - Starting attempt 144 of 147
[2024-05-10T14:17:51.931+0000] {taskinstance.py:2330} INFO - Executing <Task(PythonOperator): divide_data> on 2024-05-10 10:18:14.377791+00:00
[2024-05-10T14:17:51.937+0000] {logging_mixin.py:188} WARNING - /home/***/.local/lib/python3.12/site-packages/***/task/task_runner/standard_task_runner.py:61 DeprecationWarning: This process (pid=11308) is multi-threaded, use of fork() may lead to deadlocks in the child.
[2024-05-10T14:17:51.938+0000] {standard_task_runner.py:63} INFO - Started process 11310 to run task
[2024-05-10T14:17:51.937+0000] {standard_task_runner.py:90} INFO - Running: ['***', 'tasks', 'run', 'data_pipeline', 'divide_data', 'manual__2024-05-10T10:18:14.377791+00:00', '--job-id', '573', '--raw', '--subdir', 'DAGS_FOLDER/main_dag.py', '--cfg-path', '/tmp/tmpqobkcl8j']
[2024-05-10T14:17:51.939+0000] {standard_task_runner.py:91} INFO - Job 573: Subtask divide_data
[2024-05-10T14:17:51.948+0000] {logging_mixin.py:188} WARNING - /home/***/.local/lib/python3.12/site-packages/***/settings.py:195 DeprecationWarning: The sql_alchemy_conn option in [core] has been moved to the sql_alchemy_conn option in [database] - the old setting has been used, but please update your config.
[2024-05-10T14:17:51.973+0000] {task_command.py:426} INFO - Running <TaskInstance: data_pipeline.divide_data manual__2024-05-10T10:18:14.377791+00:00 [running]> on host dbfcb70dcca2
[2024-05-10T14:17:52.041+0000] {taskinstance.py:2648} INFO - Exporting env vars: AIRFLOW_CTX_DAG_OWNER='***' AIRFLOW_CTX_DAG_ID='data_pipeline' AIRFLOW_CTX_TASK_ID='divide_data' AIRFLOW_CTX_EXECUTION_DATE='2024-05-10T10:18:14.377791+00:00' AIRFLOW_CTX_TRY_NUMBER='144' AIRFLOW_CTX_DAG_RUN_ID='manual__2024-05-10T10:18:14.377791+00:00'
[2024-05-10T14:17:52.042+0000] {taskinstance.py:430} INFO - ::endgroup::
[2024-05-10T14:17:54.337+0000] {taskinstance.py:441} INFO - ::group::Post task execution logs
[2024-05-10T14:17:54.338+0000] {taskinstance.py:2905} ERROR - Task failed with exception
Traceback (most recent call last):
  File "/home/airflow/.local/lib/python3.12/site-packages/airflow/models/taskinstance.py", line 465, in _execute_task
    result = _execute_callable(context=context, **execute_callable_kwargs)
             ^^^^^^^^^^^^^^^^^^^^^^^^^^^^^^^^^^^^^^^^^^^^^^^^^^^^^^^^^^^^^
  File "/home/airflow/.local/lib/python3.12/site-packages/airflow/models/taskinstance.py", line 432, in _execute_callable
    return execute_callable(context=context, **execute_callable_kwargs)
           ^^^^^^^^^^^^^^^^^^^^^^^^^^^^^^^^^^^^^^^^^^^^^^^^^^^^^^^^^^^^
  File "/home/airflow/.local/lib/python3.12/site-packages/airflow/models/baseoperator.py", line 400, in wrapper
    return func(self, *args, **kwargs)
           ^^^^^^^^^^^^^^^^^^^^^^^^^^^
  File "/home/airflow/.local/lib/python3.12/site-packages/airflow/operators/python.py", line 235, in execute
    return_value = self.execute_callable()
                   ^^^^^^^^^^^^^^^^^^^^^^^
  File "/home/airflow/.local/lib/python3.12/site-packages/airflow/operators/python.py", line 252, in execute_callable
    return self.python_callable(*self.op_args, **self.op_kwargs)
           ^^^^^^^^^^^^^^^^^^^^^^^^^^^^^^^^^^^^^^^^^^^^^^^^^^^^^
  File "/opt/airflow/dags/tasks/divide_data.py", line 36, in divide_data
    title_affiliation(df, file_path_to_upload)
  File "/opt/airflow/dags/tasks/divide_data.py", line 92, in title_affiliation
    df.drop(columns=['publication_year'], inplace=True)
  File "/home/airflow/.local/lib/python3.12/site-packages/pandas/core/frame.py", line 5344, in drop
    return super().drop(
           ^^^^^^^^^^^^^
  File "/home/airflow/.local/lib/python3.12/site-packages/pandas/core/generic.py", line 4711, in drop
    obj = obj._drop_axis(labels, axis, level=level, errors=errors)
          ^^^^^^^^^^^^^^^^^^^^^^^^^^^^^^^^^^^^^^^^^^^^^^^^^^^^^^^^
  File "/home/airflow/.local/lib/python3.12/site-packages/pandas/core/generic.py", line 4753, in _drop_axis
    new_axis = axis.drop(labels, errors=errors)
               ^^^^^^^^^^^^^^^^^^^^^^^^^^^^^^^^
  File "/home/airflow/.local/lib/python3.12/site-packages/pandas/core/indexes/base.py", line 7000, in drop
    raise KeyError(f"{labels[mask].tolist()} not found in axis")
KeyError: "['publication_year'] not found in axis"
[2024-05-10T14:17:54.349+0000] {taskinstance.py:1206} INFO - Marking task as UP_FOR_RETRY. dag_id=data_pipeline, task_id=divide_data, run_id=manual__2024-05-10T10:18:14.377791+00:00, execution_date=20240510T101814, start_date=20240510T141751, end_date=20240510T141754
[2024-05-10T14:17:54.359+0000] {standard_task_runner.py:110} ERROR - Failed to execute job 573 for task divide_data ("['publication_year'] not found in axis"; 11310)
[2024-05-10T14:17:54.399+0000] {local_task_job_runner.py:240} INFO - Task exited with return code 1
[2024-05-10T14:17:54.417+0000] {taskinstance.py:3498} INFO - 0 downstream tasks scheduled from follow-on schedule check
[2024-05-10T14:17:54.418+0000] {local_task_job_runner.py:222} INFO - ::endgroup::
