[2024-05-10T10:47:07.711+0000] {local_task_job_runner.py:120} INFO - ::group::Pre task execution logs
[2024-05-10T10:47:07.735+0000] {taskinstance.py:2076} INFO - Dependencies all met for dep_context=non-requeueable deps ti=<TaskInstance: data_pipeline.divide_data manual__2024-05-10T10:18:14.377791+00:00 [queued]>
[2024-05-10T10:47:07.742+0000] {taskinstance.py:2076} INFO - Dependencies all met for dep_context=requeueable deps ti=<TaskInstance: data_pipeline.divide_data manual__2024-05-10T10:18:14.377791+00:00 [queued]>
[2024-05-10T10:47:07.742+0000] {taskinstance.py:2306} INFO - Starting attempt 10 of 13
[2024-05-10T10:47:07.752+0000] {taskinstance.py:2330} INFO - Executing <Task(PythonOperator): divide_data> on 2024-05-10 10:18:14.377791+00:00
[2024-05-10T10:47:07.758+0000] {logging_mixin.py:188} WARNING - /home/***/.local/lib/python3.12/site-packages/***/task/task_runner/standard_task_runner.py:61 DeprecationWarning: This process (pid=2068) is multi-threaded, use of fork() may lead to deadlocks in the child.
[2024-05-10T10:47:07.759+0000] {standard_task_runner.py:63} INFO - Started process 2070 to run task
[2024-05-10T10:47:07.758+0000] {standard_task_runner.py:90} INFO - Running: ['***', 'tasks', 'run', 'data_pipeline', 'divide_data', 'manual__2024-05-10T10:18:14.377791+00:00', '--job-id', '391', '--raw', '--subdir', 'DAGS_FOLDER/main_dag.py', '--cfg-path', '/tmp/tmptluz6gd0']
[2024-05-10T10:47:07.760+0000] {standard_task_runner.py:91} INFO - Job 391: Subtask divide_data
[2024-05-10T10:47:07.770+0000] {logging_mixin.py:188} WARNING - /home/***/.local/lib/python3.12/site-packages/***/settings.py:195 DeprecationWarning: The sql_alchemy_conn option in [core] has been moved to the sql_alchemy_conn option in [database] - the old setting has been used, but please update your config.
[2024-05-10T10:47:07.794+0000] {task_command.py:426} INFO - Running <TaskInstance: data_pipeline.divide_data manual__2024-05-10T10:18:14.377791+00:00 [running]> on host dbfcb70dcca2
[2024-05-10T10:47:07.860+0000] {taskinstance.py:2648} INFO - Exporting env vars: AIRFLOW_CTX_DAG_OWNER='***' AIRFLOW_CTX_DAG_ID='data_pipeline' AIRFLOW_CTX_TASK_ID='divide_data' AIRFLOW_CTX_EXECUTION_DATE='2024-05-10T10:18:14.377791+00:00' AIRFLOW_CTX_TRY_NUMBER='10' AIRFLOW_CTX_DAG_RUN_ID='manual__2024-05-10T10:18:14.377791+00:00'
[2024-05-10T10:47:07.860+0000] {taskinstance.py:430} INFO - ::endgroup::
[2024-05-10T10:47:08.040+0000] {logging_mixin.py:188} INFO - Index(['title', 'affiliation_name', 'affiliation_country', 'publication_year',
       'keywords'],
      dtype='object')
[2024-05-10T10:47:08.886+0000] {logging_mixin.py:188} INFO - HEAL
[2024-05-10T10:47:08.887+0000] {taskinstance.py:441} INFO - ::group::Post task execution logs
[2024-05-10T10:47:08.887+0000] {taskinstance.py:2905} ERROR - Task failed with exception
Traceback (most recent call last):
  File "/home/airflow/.local/lib/python3.12/site-packages/pandas/core/indexes/base.py", line 3791, in get_loc
    return self._engine.get_loc(casted_key)
           ^^^^^^^^^^^^^^^^^^^^^^^^^^^^^^^^
  File "index.pyx", line 152, in pandas._libs.index.IndexEngine.get_loc
  File "index.pyx", line 181, in pandas._libs.index.IndexEngine.get_loc
  File "pandas/_libs/hashtable_class_helper.pxi", line 7080, in pandas._libs.hashtable.PyObjectHashTable.get_item
  File "pandas/_libs/hashtable_class_helper.pxi", line 7088, in pandas._libs.hashtable.PyObjectHashTable.get_item
KeyError: 'affiliation_name'

The above exception was the direct cause of the following exception:

Traceback (most recent call last):
  File "/home/airflow/.local/lib/python3.12/site-packages/airflow/models/taskinstance.py", line 465, in _execute_task
    result = _execute_callable(context=context, **execute_callable_kwargs)
             ^^^^^^^^^^^^^^^^^^^^^^^^^^^^^^^^^^^^^^^^^^^^^^^^^^^^^^^^^^^^^
  File "/home/airflow/.local/lib/python3.12/site-packages/airflow/models/taskinstance.py", line 432, in _execute_callable
    return execute_callable(context=context, **execute_callable_kwargs)
           ^^^^^^^^^^^^^^^^^^^^^^^^^^^^^^^^^^^^^^^^^^^^^^^^^^^^^^^^^^^^
  File "/home/airflow/.local/lib/python3.12/site-packages/airflow/models/baseoperator.py", line 400, in wrapper
    return func(self, *args, **kwargs)
           ^^^^^^^^^^^^^^^^^^^^^^^^^^^
  File "/home/airflow/.local/lib/python3.12/site-packages/airflow/operators/python.py", line 235, in execute
    return_value = self.execute_callable()
                   ^^^^^^^^^^^^^^^^^^^^^^^
  File "/home/airflow/.local/lib/python3.12/site-packages/airflow/operators/python.py", line 252, in execute_callable
    return self.python_callable(*self.op_args, **self.op_kwargs)
           ^^^^^^^^^^^^^^^^^^^^^^^^^^^^^^^^^^^^^^^^^^^^^^^^^^^^^
  File "/opt/airflow/dags/tasks/divide_data.py", line 28, in divide_data
    title_affiliation(df, file_path_to_upload)
  File "/opt/airflow/dags/tasks/divide_data.py", line 60, in title_affiliation
    print(df.head()['affiliation_name'])
          ~~~~~~~~~^^^^^^^^^^^^^^^^^^^^
  File "/home/airflow/.local/lib/python3.12/site-packages/pandas/core/frame.py", line 3893, in __getitem__
    indexer = self.columns.get_loc(key)
              ^^^^^^^^^^^^^^^^^^^^^^^^^
  File "/home/airflow/.local/lib/python3.12/site-packages/pandas/core/indexes/base.py", line 3798, in get_loc
    raise KeyError(key) from err
KeyError: 'affiliation_name'
[2024-05-10T10:47:08.898+0000] {taskinstance.py:1206} INFO - Marking task as UP_FOR_RETRY. dag_id=data_pipeline, task_id=divide_data, run_id=manual__2024-05-10T10:18:14.377791+00:00, execution_date=20240510T101814, start_date=20240510T104707, end_date=20240510T104708
[2024-05-10T10:47:08.907+0000] {standard_task_runner.py:110} ERROR - Failed to execute job 391 for task divide_data ('affiliation_name'; 2070)
[2024-05-10T10:47:08.935+0000] {local_task_job_runner.py:240} INFO - Task exited with return code 1
[2024-05-10T10:47:08.950+0000] {taskinstance.py:3498} INFO - 0 downstream tasks scheduled from follow-on schedule check
[2024-05-10T10:47:08.952+0000] {local_task_job_runner.py:222} INFO - ::endgroup::
